System check identified no issues (0 silenced).
February 25, 2023 - 14:14:20
Django version 3.2.4, using settings 'reviewme_api.settings'
Starting development server at http://127.0.0.1:8000/
Quit the server with CONTROL-C.
[25/Feb/2023 14:14:25] "GET / HTTP/1.1" 200 10275
[25/Feb/2023 14:14:35] "GET /reviews/ HTTP/1.1" 200 18605
Internal Server Error: /reviews/
Traceback (most recent call last):
  File "/workspace/.pip-modules/lib/python3.8/site-packages/django/core/handlers/exception.py", line 47, in inner
    response = get_response(request)
  File "/workspace/.pip-modules/lib/python3.8/site-packages/django/core/handlers/base.py", line 181, in _get_response
    response = wrapped_callback(request, *callback_args, **callback_kwargs)
  File "/workspace/.pip-modules/lib/python3.8/site-packages/django/views/decorators/csrf.py", line 54, in wrapped_view
    return view_func(*args, **kwargs)
  File "/workspace/.pip-modules/lib/python3.8/site-packages/django/views/generic/base.py", line 70, in view
    return self.dispatch(request, *args, **kwargs)
  File "/workspace/.pip-modules/lib/python3.8/site-packages/rest_framework/views.py", line 509, in dispatch
    response = self.handle_exception(exc)
  File "/workspace/.pip-modules/lib/python3.8/site-packages/rest_framework/views.py", line 469, in handle_exception
    self.raise_uncaught_exception(exc)
  File "/workspace/.pip-modules/lib/python3.8/site-packages/rest_framework/views.py", line 480, in raise_uncaught_exception
    raise exc
  File "/workspace/.pip-modules/lib/python3.8/site-packages/rest_framework/views.py", line 506, in dispatch
    response = handler(request, *args, **kwargs)
  File "/workspace/.pip-modules/lib/python3.8/site-packages/rest_framework/generics.py", line 242, in post
    return self.create(request, *args, **kwargs)
  File "/workspace/.pip-modules/lib/python3.8/site-packages/rest_framework/mixins.py", line 18, in create
    serializer.is_valid(raise_exception=True)
  File "/workspace/.pip-modules/lib/python3.8/site-packages/rest_framework/serializers.py", line 220, in is_valid
    self._validated_data = self.run_validation(self.initial_data)
  File "/workspace/.pip-modules/lib/python3.8/site-packages/rest_framework/serializers.py", line 419, in run_validation
    value = self.to_internal_value(data)
  File "/workspace/.pip-modules/lib/python3.8/site-packages/rest_framework/serializers.py", line 476, in to_internal_value
    validated_value = field.run_validation(primitive_value)
  File "/workspace/.pip-modules/lib/python3.8/site-packages/rest_framework/fields.py", line 569, in run_validation
    self.run_validators(value)
  File "/workspace/.pip-modules/lib/python3.8/site-packages/rest_framework/fields.py", line 593, in run_validators
    validator(value)
  File "/workspace/.pip-modules/lib/python3.8/site-packages/django/core/validators.py", line 358, in __call__
    if self.compare(cleaned, limit_value):
  File "/workspace/.pip-modules/lib/python3.8/site-packages/django/core/validators.py", line 392, in compare
    return a < b
TypeError: '<' not supported between instances of 'str' and 'int'
[25/Feb/2023 14:14:39] "POST /reviews/ HTTP/1.1" 500 145446
/workspace/reviewme-api/reviews/serializers.py changed, reloading.
Watching for file changes with StatReloader
Performing system checks...

System check identified no issues (0 silenced).
February 25, 2023 - 14:18:37
Django version 3.2.4, using settings 'reviewme_api.settings'
Starting development server at http://127.0.0.1:8000/
Quit the server with CONTROL-C.
Value:  <class 'django.core.files.uploadedfile.InMemoryUploadedFile'> Screenshot 2023-02-23 22.20.17.png
Internal Server Error: /reviews/
Traceback (most recent call last):
  File "/workspace/.pip-modules/lib/python3.8/site-packages/django/core/handlers/exception.py", line 47, in inner
    response = get_response(request)
  File "/workspace/.pip-modules/lib/python3.8/site-packages/django/core/handlers/base.py", line 181, in _get_response
    response = wrapped_callback(request, *callback_args, **callback_kwargs)
  File "/workspace/.pip-modules/lib/python3.8/site-packages/django/views/decorators/csrf.py", line 54, in wrapped_view
    return view_func(*args, **kwargs)
  File "/workspace/.pip-modules/lib/python3.8/site-packages/django/views/generic/base.py", line 70, in view
    return self.dispatch(request, *args, **kwargs)
  File "/workspace/.pip-modules/lib/python3.8/site-packages/rest_framework/views.py", line 509, in dispatch
    response = self.handle_exception(exc)
  File "/workspace/.pip-modules/lib/python3.8/site-packages/rest_framework/views.py", line 469, in handle_exception
    self.raise_uncaught_exception(exc)
  File "/workspace/.pip-modules/lib/python3.8/site-packages/rest_framework/views.py", line 480, in raise_uncaught_exception
    raise exc
  File "/workspace/.pip-modules/lib/python3.8/site-packages/rest_framework/views.py", line 506, in dispatch
    response = handler(request, *args, **kwargs)
  File "/workspace/.pip-modules/lib/python3.8/site-packages/rest_framework/generics.py", line 242, in post
    return self.create(request, *args, **kwargs)
  File "/workspace/.pip-modules/lib/python3.8/site-packages/rest_framework/mixins.py", line 18, in create
    serializer.is_valid(raise_exception=True)
  File "/workspace/.pip-modules/lib/python3.8/site-packages/rest_framework/serializers.py", line 220, in is_valid
    self._validated_data = self.run_validation(self.initial_data)
  File "/workspace/.pip-modules/lib/python3.8/site-packages/rest_framework/serializers.py", line 419, in run_validation
    value = self.to_internal_value(data)
  File "/workspace/.pip-modules/lib/python3.8/site-packages/rest_framework/serializers.py", line 476, in to_internal_value
    validated_value = field.run_validation(primitive_value)
  File "/workspace/.pip-modules/lib/python3.8/site-packages/rest_framework/fields.py", line 569, in run_validation
    self.run_validators(value)
  File "/workspace/.pip-modules/lib/python3.8/site-packages/rest_framework/fields.py", line 593, in run_validators
    validator(value)
  File "/workspace/.pip-modules/lib/python3.8/site-packages/django/core/validators.py", line 358, in __call__
    if self.compare(cleaned, limit_value):
  File "/workspace/.pip-modules/lib/python3.8/site-packages/django/core/validators.py", line 392, in compare
    return a < b
TypeError: '<' not supported between instances of 'str' and 'int'
[25/Feb/2023 14:19:21] "POST /reviews/ HTTP/1.1" 500 146346
Value:  <class 'django.core.files.uploadedfile.InMemoryUploadedFile'> Screenshot 2023-02-23 22.20.17.png
Internal Server Error: /reviews/
Traceback (most recent call last):
  File "/workspace/.pip-modules/lib/python3.8/site-packages/django/core/handlers/exception.py", line 47, in inner
    response = get_response(request)
  File "/workspace/.pip-modules/lib/python3.8/site-packages/django/core/handlers/base.py", line 181, in _get_response
    response = wrapped_callback(request, *callback_args, **callback_kwargs)
  File "/workspace/.pip-modules/lib/python3.8/site-packages/django/views/decorators/csrf.py", line 54, in wrapped_view
    return view_func(*args, **kwargs)
  File "/workspace/.pip-modules/lib/python3.8/site-packages/django/views/generic/base.py", line 70, in view
    return self.dispatch(request, *args, **kwargs)
  File "/workspace/.pip-modules/lib/python3.8/site-packages/rest_framework/views.py", line 509, in dispatch
    response = self.handle_exception(exc)
  File "/workspace/.pip-modules/lib/python3.8/site-packages/rest_framework/views.py", line 469, in handle_exception
    self.raise_uncaught_exception(exc)
  File "/workspace/.pip-modules/lib/python3.8/site-packages/rest_framework/views.py", line 480, in raise_uncaught_exception
    raise exc
  File "/workspace/.pip-modules/lib/python3.8/site-packages/rest_framework/views.py", line 506, in dispatch
    response = handler(request, *args, **kwargs)
  File "/workspace/.pip-modules/lib/python3.8/site-packages/rest_framework/generics.py", line 242, in post
    return self.create(request, *args, **kwargs)
  File "/workspace/.pip-modules/lib/python3.8/site-packages/rest_framework/mixins.py", line 18, in create
    serializer.is_valid(raise_exception=True)
  File "/workspace/.pip-modules/lib/python3.8/site-packages/rest_framework/serializers.py", line 220, in is_valid
    self._validated_data = self.run_validation(self.initial_data)
  File "/workspace/.pip-modules/lib/python3.8/site-packages/rest_framework/serializers.py", line 419, in run_validation
    value = self.to_internal_value(data)
  File "/workspace/.pip-modules/lib/python3.8/site-packages/rest_framework/serializers.py", line 476, in to_internal_value
    validated_value = field.run_validation(primitive_value)
  File "/workspace/.pip-modules/lib/python3.8/site-packages/rest_framework/fields.py", line 569, in run_validation
    self.run_validators(value)
  File "/workspace/.pip-modules/lib/python3.8/site-packages/rest_framework/fields.py", line 593, in run_validators
    validator(value)
  File "/workspace/.pip-modules/lib/python3.8/site-packages/django/core/validators.py", line 358, in __call__
    if self.compare(cleaned, limit_value):
  File "/workspace/.pip-modules/lib/python3.8/site-packages/django/core/validators.py", line 392, in compare
    return a < b
TypeError: '<' not supported between instances of 'str' and 'int'
[25/Feb/2023 14:20:43] "POST /reviews/ HTTP/1.1" 500 146346
/workspace/reviewme-api/reviews/serializers.py changed, reloading.
Watching for file changes with StatReloader
Performing system checks...

System check identified no issues (0 silenced).
February 25, 2023 - 14:20:58
Django version 3.2.4, using settings 'reviewme_api.settings'
Starting development server at http://127.0.0.1:8000/
Quit the server with CONTROL-C.
[25/Feb/2023 14:21:04] "GET / HTTP/1.1" 200 10275
[25/Feb/2023 14:21:14] "GET /reviews/ HTTP/1.1" 200 18605
Value:  <class 'int'> 95640
Internal Server Error: /reviews/
Traceback (most recent call last):
  File "/workspace/.pip-modules/lib/python3.8/site-packages/django/core/handlers/exception.py", line 47, in inner
    response = get_response(request)
  File "/workspace/.pip-modules/lib/python3.8/site-packages/django/core/handlers/base.py", line 181, in _get_response
    response = wrapped_callback(request, *callback_args, **callback_kwargs)
  File "/workspace/.pip-modules/lib/python3.8/site-packages/django/views/decorators/csrf.py", line 54, in wrapped_view
    return view_func(*args, **kwargs)
  File "/workspace/.pip-modules/lib/python3.8/site-packages/django/views/generic/base.py", line 70, in view
    return self.dispatch(request, *args, **kwargs)
  File "/workspace/.pip-modules/lib/python3.8/site-packages/rest_framework/views.py", line 509, in dispatch
    response = self.handle_exception(exc)
  File "/workspace/.pip-modules/lib/python3.8/site-packages/rest_framework/views.py", line 469, in handle_exception
    self.raise_uncaught_exception(exc)
  File "/workspace/.pip-modules/lib/python3.8/site-packages/rest_framework/views.py", line 480, in raise_uncaught_exception
    raise exc
  File "/workspace/.pip-modules/lib/python3.8/site-packages/rest_framework/views.py", line 506, in dispatch
    response = handler(request, *args, **kwargs)
  File "/workspace/.pip-modules/lib/python3.8/site-packages/rest_framework/generics.py", line 242, in post
    return self.create(request, *args, **kwargs)
  File "/workspace/.pip-modules/lib/python3.8/site-packages/rest_framework/mixins.py", line 18, in create
    serializer.is_valid(raise_exception=True)
  File "/workspace/.pip-modules/lib/python3.8/site-packages/rest_framework/serializers.py", line 220, in is_valid
    self._validated_data = self.run_validation(self.initial_data)
  File "/workspace/.pip-modules/lib/python3.8/site-packages/rest_framework/serializers.py", line 419, in run_validation
    value = self.to_internal_value(data)
  File "/workspace/.pip-modules/lib/python3.8/site-packages/rest_framework/serializers.py", line 476, in to_internal_value
    validated_value = field.run_validation(primitive_value)
  File "/workspace/.pip-modules/lib/python3.8/site-packages/rest_framework/fields.py", line 569, in run_validation
    self.run_validators(value)
  File "/workspace/.pip-modules/lib/python3.8/site-packages/rest_framework/fields.py", line 593, in run_validators
    validator(value)
  File "/workspace/.pip-modules/lib/python3.8/site-packages/django/core/validators.py", line 358, in __call__
    if self.compare(cleaned, limit_value):
  File "/workspace/.pip-modules/lib/python3.8/site-packages/django/core/validators.py", line 392, in compare
    return a < b
TypeError: '<' not supported between instances of 'str' and 'int'
[25/Feb/2023 14:21:21] "POST /reviews/ HTTP/1.1" 500 146434
